DEBUG:safe:Reading from cache file /tmp/safe-0.4.words.cache
INFO:application.Program:SETTING UP LOGGER
INFO:werkzeug: * Running on http://0.0.0.0:5000/ (Press CTRL+C to quit)
INFO:werkzeug:172.18.0.1 - - [30/Apr/2020 07:39:53] "[33mGET / HTTP/1.1[0m" 404 -
INFO:werkzeug:172.18.0.1 - - [30/Apr/2020 07:39:53] "[33mGET / HTTP/1.1[0m" 404 -
INFO:werkzeug:172.18.0.1 - - [30/Apr/2020 07:39:54] "[33mGET / HTTP/1.1[0m" 404 -
INFO:werkzeug:172.18.0.1 - - [30/Apr/2020 07:40:06] "[33mGET / HTTP/1.1[0m" 404 -
ERROR:application.Program:Exception on /minecraft/break [GET]
Traceback (most recent call last):
  File "/home/runner/.local/share/virtualenvs/python3/lib/python3.8/site-packages/flask/app.py", line 1950, in full_dispatch_request
    rv = self.dispatch_request()
  File "/home/runner/.local/share/virtualenvs/python3/lib/python3.8/site-packages/flask/app.py", line 1936, in dispatch_request
    return self.view_functions[rule.endpoint](**req.view_args)
  File "/home/runner/Serverlist/application/MCRoutes.py", line 55, in breakPage
    print(1+"2")
TypeError: unsupported operand type(s) for +: 'int' and 'str'

During handling of the above exception, another exception occurred:

Traceback (most recent call last):
  File "/home/runner/.local/share/virtualenvs/python3/lib/python3.8/site-packages/flask/app.py", line 2447, in wsgi_app
    response = self.full_dispatch_request()
  File "/home/runner/.local/share/virtualenvs/python3/lib/python3.8/site-packages/flask/app.py", line 1952, in full_dispatch_request
    rv = self.handle_user_exception(e)
  File "/home/runner/.local/share/virtualenvs/python3/lib/python3.8/site-packages/flask/app.py", line 1822, in handle_user_exception
    return handler(e)
  File "/home/runner/Serverlist/application/ErrorHandler.py", line 10, in internal_error
    result = error.format_exc()
AttributeError: 'TypeError' object has no attribute 'format_exc'
INFO:werkzeug:172.18.0.1 - - [30/Apr/2020 07:40:15] "[35m[1mGET /minecraft/break HTTP/1.1[0m" 500 -
ERROR:werkzeug:Error on request:
Traceback (most recent call last):
  File "/home/runner/.local/share/virtualenvs/python3/lib/python3.8/site-packages/flask/app.py", line 1950, in full_dispatch_request
    rv = self.dispatch_request()
  File "/home/runner/.local/share/virtualenvs/python3/lib/python3.8/site-packages/flask/app.py", line 1936, in dispatch_request
    return self.view_functions[rule.endpoint](**req.view_args)
  File "/home/runner/Serverlist/application/MCRoutes.py", line 55, in breakPage
    print(1+"2")
TypeError: unsupported operand type(s) for +: 'int' and 'str'

During handling of the above exception, another exception occurred:

Traceback (most recent call last):
  File "/home/runner/.local/share/virtualenvs/python3/lib/python3.8/site-packages/flask/app.py", line 2447, in wsgi_app
    response = self.full_dispatch_request()
  File "/home/runner/.local/share/virtualenvs/python3/lib/python3.8/site-packages/flask/app.py", line 1952, in full_dispatch_request
    rv = self.handle_user_exception(e)
  File "/home/runner/.local/share/virtualenvs/python3/lib/python3.8/site-packages/flask/app.py", line 1822, in handle_user_exception
    return handler(e)
  File "/home/runner/Serverlist/application/ErrorHandler.py", line 10, in internal_error
    result = error.format_exc()
AttributeError: 'TypeError' object has no attribute 'format_exc'

During handling of the above exception, another exception occurred:

Traceback (most recent call last):
  File "/home/runner/.local/share/virtualenvs/python3/lib/python3.8/site-packages/werkzeug/serving.py", line 323, in run_wsgi
    execute(self.server.app)
  File "/home/runner/.local/share/virtualenvs/python3/lib/python3.8/site-packages/werkzeug/serving.py", line 312, in execute
    application_iter = app(environ, start_response)
  File "/home/runner/.local/share/virtualenvs/python3/lib/python3.8/site-packages/flask/app.py", line 2464, in __call__
    return self.wsgi_app(environ, start_response)
  File "/home/runner/.local/share/virtualenvs/python3/lib/python3.8/site-packages/flask/app.py", line 2450, in wsgi_app
    response = self.handle_exception(e)
  File "/home/runner/.local/share/virtualenvs/python3/lib/python3.8/site-packages/flask/app.py", line 1879, in handle_exception
    server_error = handler(server_error)
  File "/home/runner/Serverlist/application/ErrorHandler.py", line 10, in internal_error
    result = error.format_exc()
AttributeError: 'InternalServerError' object has no attribute 'format_exc'
INFO:werkzeug:172.18.0.1 - - [30/Apr/2020 07:41:06] "[33mGET / HTTP/1.1[0m" 404 -
INFO:werkzeug:172.18.0.1 - - [30/Apr/2020 07:42:06] "[33mGET / HTTP/1.1[0m" 404 -
